#!/usr/bin/env python3
"""
Integration tests for provider failure scenarios and fallback behavior.
"""

import pytest
import asyncio
from unittest.mock import Mock, AsyncMock, patch


class TestProviderFailureScenarios:
    """Test provider failure handling and recovery"""
    
    @pytest.mark.asyncio
    async def test_network_failure_simulation(self):
        """Test provider behavior during network failures"""
        # Create mock provider
        mock_provider = Mock()
        mock_provider.get_stock_quote = AsyncMock(side_effect=TimeoutError("Network timeout"))
        
        with pytest.raises(TimeoutError):
            await mock_provider.get_stock_quote("AAPL")
    
    @pytest.mark.asyncio
    async def test_authentication_failure_handling(self):
        """Test authentication failure detection and handling"""
        mock_auth = Mock()
        mock_auth.login = Mock(return_value=False)
        
        # Simulate auth failure
        async def ensure_auth():
            if not mock_auth.login():
                raise Exception("Authentication failed after 3 attempts")
        
        with pytest.raises(Exception) as exc_info:
            await ensure_auth()
        
        assert "authentication failed" in str(exc_info.value).lower()
    
    @pytest.mark.asyncio
    async def test_authentication_retry_on_stale_session(self):
        """Test that stale authentication is detected and retried"""
        mock_auth = Mock()
        mock_auth.login = Mock(return_value=True)
        
        # Simulate successful auth
        authenticated = mock_auth.login()
        assert authenticated is True
    
    @pytest.mark.asyncio
    async def test_provider_timeout_handling(self):
        """Test provider timeout scenarios"""
        mock_provider = Mock()
        mock_provider.get_stock_quote = AsyncMock(return_value={"error": "Request timeout"})
        
        result = await mock_provider.get_stock_quote("AAPL")
        assert "error" in result
    
    @pytest.mark.asyncio
    async def test_invalid_api_key_handling(self):
        """Test handling of invalid API keys"""
        mock_provider = Mock()
        mock_provider.get_stock_quote = AsyncMock(return_value={"error": "Invalid API key"})
        
        result = await mock_provider.get_stock_quote("AAPL")
        assert "error" in result
    
    @pytest.mark.asyncio
    async def test_rate_limit_exceeded_handling(self):
        """Test handling of rate limit exceeded errors"""
        mock_provider = Mock()
        mock_provider.get_stock_quote = AsyncMock(return_value={"error": "Rate limit exceeded"})
        
        result = await mock_provider.get_stock_quote("AAPL")
        assert "error" in result


class TestProviderFallbackChain:
    """Test provider chain fallback logic"""
    
    @pytest.mark.asyncio
    async def test_fallback_to_secondary_provider(self):
        """Test that service falls back to secondary provider on primary failure"""
        # Mock primary provider fails
        mock_primary = Mock()
        mock_primary.get_stock_quote = AsyncMock(side_effect=Exception("Primary failed"))
        
        # Mock secondary provider succeeds
        mock_secondary = Mock()
        mock_secondary.get_stock_quote = AsyncMock(return_value={
            "symbol": "AAPL", 
            "data": {"c": 150.0}
        })
        
        # Simulate fallback logic
        try:
            result = await mock_primary.get_stock_quote("AAPL")
        except Exception:
            result = await mock_secondary.get_stock_quote("AAPL")
        
        assert result["symbol"] == "AAPL"
    
    @pytest.mark.asyncio
    async def test_fallback_chain_exhaustion(self):
        """Test behavior when all providers in chain fail"""
        mock_provider1 = Mock()
        mock_provider1.get_stock_quote = AsyncMock(side_effect=Exception("Provider 1 failed"))
        
        mock_provider2 = Mock()
        mock_provider2.get_stock_quote = AsyncMock(side_effect=Exception("Provider 2 failed"))
        
        # Both fail
        with pytest.raises(Exception):
            try:
                await mock_provider1.get_stock_quote("AAPL")
            except Exception:
                await mock_provider2.get_stock_quote("AAPL")
    
    @pytest.mark.asyncio
    async def test_fallback_timing_and_order(self):
        """Test that fallback happens in correct order"""
        call_order = []
        
        mock_p1 = Mock()
        async def p1_call(*args):
            call_order.append("p1")
            raise Exception("P1 failed")
        mock_p1.get_stock_quote = AsyncMock(side_effect=p1_call)
        
        mock_p2 = Mock()
        async def p2_call(*args):
            call_order.append("p2")
            return {"symbol": "AAPL", "data": {"c": 150.0}}
        mock_p2.get_stock_quote = AsyncMock(side_effect=p2_call)
        
        # Try p1, then p2
        try:
            await mock_p1.get_stock_quote("AAPL")
        except Exception:
            await mock_p2.get_stock_quote("AAPL")
        
        assert call_order == ["p1", "p2"]
    
    @pytest.mark.asyncio
    async def test_provider_recovery_after_failure(self):
        """Test that provider can recover after temporary failure"""
        call_count = {"count": 0}
        
        async def intermittent(*args):
            call_count["count"] += 1
            if call_count["count"] == 1:
                raise Exception("Temporary error")
            return {"symbol": "AAPL", "data": {"c": 150.0}}
        
        mock_provider = Mock()
        mock_provider.get_stock_quote = AsyncMock(side_effect=intermittent)
        
        # First call fails
        with pytest.raises(Exception):
            await mock_provider.get_stock_quote("AAPL")
        
        # Second call succeeds
        result = await mock_provider.get_stock_quote("AAPL")
        assert result["symbol"] == "AAPL"


class TestProviderHealthChecks:
    """Test provider health check functionality"""
    
    @pytest.mark.asyncio
    async def test_health_check_detects_auth_failure(self):
        """Test that health check detects authentication failures"""
        mock_provider = Mock()
        mock_provider.health_check = AsyncMock(return_value=False)
        
        health = await mock_provider.health_check()
        assert health is False
    
    @pytest.mark.asyncio
    async def test_health_check_detects_network_failure(self):
        """Test that health check detects network failures"""
        mock_provider = Mock()
        mock_provider.health_check = AsyncMock(return_value=False)
        
        health = await mock_provider.health_check()
        assert health is False
    
    @pytest.mark.asyncio
    async def test_health_check_passes_when_healthy(self):
        """Test that health check passes for healthy provider"""
        mock_provider = Mock()
        mock_provider.health_check = AsyncMock(return_value=True)
        
        health = await mock_provider.health_check()
        assert health is True


class TestConcurrentFailures:
    """Test handling of concurrent provider failures"""
    
    @pytest.mark.asyncio
    async def test_concurrent_requests_with_failures(self):
        """Test multiple concurrent requests when provider fails"""
        call_count = {"count": 0}
        
        async def intermittent(*args):
            call_count["count"] += 1
            if call_count["count"] % 2 == 0:
                raise Exception("Intermittent failure")
            return {"symbol": args[0], "data": {"c": 150.0}}
        
        mock_provider = Mock()
        mock_provider.get_stock_quote = AsyncMock(side_effect=intermittent)
        
        # Make concurrent requests
        tasks = [mock_provider.get_stock_quote(f"SYM{i}") for i in range(4)]
        results = await asyncio.gather(*tasks, return_exceptions=True)
        
        assert len(results) == 4
        successes = [r for r in results if not isinstance(r, Exception)]
        failures = [r for r in results if isinstance(r, Exception)]
        assert len(successes) == 2
        assert len(failures) == 2
    
    @pytest.mark.asyncio
    async def test_provider_isolation_on_failure(self):
        """Test that one provider's failure doesn't affect others"""
        mock_p1 = Mock()
        mock_p1.get_stock_quote = AsyncMock(side_effect=Exception("P1 down"))
        
        mock_p2 = Mock()
        mock_p2.get_stock_quote = AsyncMock(return_value={"symbol": "AAPL", "data": {"c": 150.0}})
        
        # P1 fails but P2 works
        try:
            await mock_p1.get_stock_quote("AAPL")
        except Exception:
            result = await mock_p2.get_stock_quote("AAPL")
        
        assert result["symbol"] == "AAPL"
